<?xml version="1.0" encoding="UTF-8"?>
<!-- Generated by org.testng.reporters.JUnitReportReporter -->
<testsuite hostname="BA-000095818" failures="1" tests="5" name="atulpracticecompany.tests.ErrorValidationTest" time="96.363" errors="0" timestamp="2023-01-26T11:53:17 EST" skipped="3">
  <testcase classname="atulpracticecompany.tests.ErrorValidationTest" name="loginErrorValidation" time="8.572">
    <failure message="expected [Incorrect email or password.] but found [Incorrect  or password.]" type="java.lang.AssertionError">
      <![CDATA[java.lang.AssertionError: expected [Incorrect email or password.] but found [Incorrect  or password.]
at org.testng.Assert.fail(Assert.java:110)
at org.testng.Assert.failNotEquals(Assert.java:1577)
at org.testng.Assert.assertEqualsImpl(Assert.java:149)
at org.testng.Assert.assertEquals(Assert.java:131)
at org.testng.Assert.assertEquals(Assert.java:655)
at org.testng.Assert.assertEquals(Assert.java:665)
at atulpracticecompany.tests.ErrorValidationTest.loginErrorValidation(ErrorValidationTest.java:32)
at java.base/jdk.internal.reflect.NativeMethodAccessorImpl.invoke0(Native Method)
at java.base/jdk.internal.reflect.NativeMethodAccessorImpl.invoke(Unknown Source)
at java.base/jdk.internal.reflect.DelegatingMethodAccessorImpl.invoke(Unknown Source)
at java.base/java.lang.reflect.Method.invoke(Unknown Source)
at org.testng.internal.invokers.MethodInvocationHelper.invokeMethod(MethodInvocationHelper.java:139)
at org.testng.internal.invokers.TestInvoker.invokeMethod(TestInvoker.java:677)
at org.testng.internal.invokers.TestInvoker.retryFailed(TestInvoker.java:263)
at org.testng.internal.invokers.MethodRunner.runInSequence(MethodRunner.java:62)
at org.testng.internal.invokers.TestInvoker$MethodInvocationAgent.invoke(TestInvoker.java:969)
at org.testng.internal.invokers.TestInvoker.invokeTestMethods(TestInvoker.java:194)
at org.testng.internal.invokers.TestMethodWorker.invokeTestMethods(TestMethodWorker.java:148)
at org.testng.internal.invokers.TestMethodWorker.run(TestMethodWorker.java:128)
at java.base/java.util.ArrayList.forEach(Unknown Source)
at org.testng.TestRunner.privateRun(TestRunner.java:829)
at org.testng.TestRunner.run(TestRunner.java:602)
at org.testng.SuiteRunner.runTest(SuiteRunner.java:437)
at org.testng.SuiteRunner$SuiteWorker.run(SuiteRunner.java:475)
at org.testng.internal.thread.ThreadUtil.lambda$execute$0(ThreadUtil.java:58)
at java.base/java.util.concurrent.FutureTask.run(Unknown Source)
at java.base/java.util.concurrent.ThreadPoolExecutor.runWorker(Unknown Source)
at java.base/java.util.concurrent.ThreadPoolExecutor$Worker.run(Unknown Source)
at java.base/java.lang.Thread.run(Unknown Source)
]]>
    </failure>
  </testcase> <!-- loginErrorValidation -->
  <system-out/>
  <testcase classname="atulpracticecompany.tests.ErrorValidationTest" name="loginErrorValidation" time="11.693">
    <skipped/>
  </testcase> <!-- loginErrorValidation -->
  <system-out/>
  <testcase classname="atulpracticecompany.tests.ErrorValidationTest" name="loginErrorValidation" time="56.522">
    <skipped/>
  </testcase> <!-- loginErrorValidation -->
  <system-out/>
  <testcase classname="atulpracticecompany.tests.ErrorValidationTest" name="productErrorValidation" time="10.865"/>
  <system-out/>
  <testcase classname="atulpracticecompany.tests.ErrorValidationTest" name="loginErrorValidation" time="8.711">
    <skipped/>
  </testcase> <!-- loginErrorValidation -->
  <system-out/>
</testsuite> <!-- atulpracticecompany.tests.ErrorValidationTest -->
